Workbook
Name WD_Well: 'Well Data'!$B$10
Name WD_Field: 'Well Data'!$B$11
Name WD_Rig: 'Well Data'!$B$12
Name WD_Engineer: 'Well Data'!$B$13
Name WD_Date: 'Well Data'!$B$14
Name WD_MD: 'Well Data'!$B$20
Name WD_TVD: 'Well Data'!$B$21
Name WD_ShoeMD: 'Well Data'!$B$22
Name WD_ShoeTVD: 'Well Data'!$B$23
Name WD_HoleDiam: 'Well Data'!$B$24
Name WD_CsgID: 'Well Data'!$B$25
Name WD_PerfTVD: 'Well Data'!$B$26
Name WD_OMW: 'Well Data'!$B$31
Name WD_PV: 'Well Data'!$B$32
Name WD_YP: 'Well Data'!$B$33
Name WD_LOT: 'Well Data'!$B$34
Name WD_FracGrad: 'Well Data'!$B$35
Name WD_ResP: 'Well Data'!$B$36
Name WD_SCR: 'Well Data'!$B$41
Name WD_SPR: 'Well Data'!$B$42
Name WD_KillRate: 'Well Data'!$B$43
Name WD_BlockWt: 'Well Data'!$B$48
Name WD_WOB: 'Well Data'!$B$49
Name WD_BitTq: 'Well Data'!$B$50
Name WD_TJOD: 'Well Data'!$B$51
Name WD_DPWt: 'Well Data'!$B$52
Name WD_BHAWt: 'Well Data'!$B$53
Name WD_BHALen: 'Well Data'!$B$54
Name WD_MuCased: 'Well Data'!$B$55
Name WD_MuOpen: 'Well Data'!$B$56
Name WD_WaterDepth: 'Well Data'!$B$61
Name WD_AirGap: 'Well Data'!$B$62
Name WD_SWGrad: 'Well Data'!$B$63
Name WD_CLF: 'Well Data'!$B$64
Name WD_TbgOD: 'Well Data'!$B$69
Name WD_TbgID: 'Well Data'!$B$70
Name TL_Names: 'Tubular Library'!$A$9:$A$47
Name TL_Table: 'Tubular Library'!$A$9:$D$47
Name RU_Names: 'Surface Rig-Up'!$A$9:$A$28
Name RU_Table: 'Surface Rig-Up'!$A$9:$E$28

Sheet Cover
A1: Drilling, Completion & Intervention Engineering Suite
B4: How to use
B5: Yellow cells | C5: User inputs - overwrite the example values with your well data.
B6: Blue cells | C6: Linked to the Well Data master sheet - update the well there once, or overwrite locally for a one-off value.
B7: Green cells | C7: Live calculated results - do not type over them.
B8: Red / amber highlights | C8: Automatic alarms on status cells (limits exceeded, buckling, marginal margins).
B9: SI columns | C9: Every value is mirrored to SI units automatically (columns D-E).
B10: Notes / Equation | C10: The governing equation for every calculation is written out in column F.
B11: Protection | C11: Sheets are protected with no password so formulas can't be typed over by accident - Review > Unprotect Sheet to edit structure.
B13: Field units are primary (ppg, psi, ft, in, bbl). All formulas are standard API/IADC/IWCF-form oilfield equations; see each sheet's notes for assumptions.
B15: Reference
B16: Well Data | C16: Single source of well inputs (WD_* named cells) feeding the linked light-blue cells on other sheets
B17: Tubular Library | C17: API tubular catalog (TL_Names/TL_Table named ranges), capacities/displacements per size, and a lookup calculator
B18: Unit Converter | C18: Live converters (density, pressure, volume, flow, force...) and conversion factor table
B19: Wellbore Schematic | C19: Customizable wellbore schematic: casing strings, tubing, packer, TRSV, perfs, PBTD drawn to scale on a chart
B21: Drilling
B22: Mud & Hydrostatics | C22: Pressure gradients, hydrostatic pressure, EMW, ECD, barite weight-up, dilution
B23: Capacities & Displacement | C23: Capacities, displacements, pump output, stroke/lag times, tripping and slug volumes
B24: Kill Sheet | C24: Full kill sheet: string & annulus component tables, KMW, ICP, FCP, survey-driven step-down schedule for deviated/horizontal wells, kill plot
B25: Kill Form | C25: One-page printable kill sheet (all values pulled live from Kill Sheet / Well Data)
B26: Kill Sheet - Subsea | C26: Subsea supplement: CLF-corrected MAASP and choke pressure, choke line volume, kill mud weight, riser margin, disconnected-riser BHP
B27: Well Control | C27: Kick tolerance, MAASP, margins, gas migration/expansion, kill mud, volumetric control
B28: Hydraulics | C28: Velocities, slip velocity, PV/YP, n and K, annular pressure loss, ECD, surge/swab
B29: Bit Hydraulics | C29: TFA, nozzle velocity, bit pressure drop, HHP, HSI, impact force, optimization targets
B30: Drill String & Tension | C30: Buoyancy factor, hook load, MOP, DC length, pipe stretch, slip crush, critical RPM, ton-miles
B31: Directional Drilling | C31: DLS, minimum curvature, closure and vertical section, build planning, slide/rotate split
B32: Directional Survey | C32: Survey upload table (100 stations, minimum curvature), TVD/NS/EW/VS/DLS, profile & plan charts, MD->TVD interpolator
B33: Torque & Drag | C33: Johancsik soft-string T&D over the Directional Survey: hookloads, surface torque, Dawson-Paslay buckling flags, profile charts
... B40: Procedure - Drilling | C40: Editable template drilling procedure whose step text embeds live Well Data values
B42: Completions
B43: Completion Fluids & Brines | C43: Brine density for overbalance, blending, temperature correction, CaCl2 weight-up, packer fluids
B44: Tubing & Packer Forces | C44: Tubing areas and volumes, stretch, packer setting force, Lubinski force-length effects, buckling
B45: Tubing Stress Analysis | C45: Bellarby-style TSA screening: piston/ballooning/thermal axial loads, Barlow burst, triaxial von Mises with design factors, buckling, APB
B46: Perforating | C46: Optimal underbalance, wellbore pressure at perfs, cushion design, perf flow area, gun string totals
B47: Stimulation & Fracturing | C47: Frac/closure gradients, BHTP and STP, HHP, perf friction, proppant schedule totals, acid volumes
B48: Inflow & Productivity | C48: PI, Darcy radial rate, Vogel IPR and Qmax, gas C-and-n deliverability, AOF, skin pressure drop
B49: Nodal Analysis | C49: Vogel IPR vs simplified VLP, 21-point system curves, interpolated natural-flow operating point and IPR/VLP chart
B50: ESP Design | C50: ESP sizing: PIP and free gas at intake, TDH, stages, motor HP/kW, surface voltage, current and kVA
B51: Gas Lift Design | C51: Gas lift: 10-valve load-fluid spacing table with spacing diagram, injection gas rate and valve test-rack pressures
B52: Rod Pump Design | C52: Beam pump: displacement, PPRL/MPRL, counterbalance, peak torque, motor HP, Goodman check and plunger stroke
...

Sheet Well Data
A1: Well Data - Master Inputs
A2: Enter the well once; light-blue cells across the workbook pull from here (overwrite them locally when a calc needs a different value)
A4: Parameter | B4: Value | C4: Unit | D4: SI Value | E4: SI Unit | F4: Notes / Equation
A6: Well Identification
A8: Identification
F9: Free text - appears on the printable Kill Form.
A10: Well name | B10: EXAMPLE 1-H
A11: Field / lease | B11: EXAMPLE FIELD
A12: Rig | B12: RIG 00
A13: Engineer | B13: K. Keel
A14: Date | B14: 2026-08-18
A16: Depths & Geometry
A18: Depths & Geometry
F19: TVDs from the Directional Survey sheet (TVD at TD cell).
A20: Bit / TD measured depth | B20: 10500 | C20: ft | D20: =IFERROR($B$20*0.3048,NA()) | E20: m
A21: Bit / TD true vertical depth | B21: 5573 | C21: ft | D21: =IFERROR($B$21*0.3048,NA()) | E21: m
A22: Casing shoe MD | B22: 5900 | C22: ft | D22: =IFERROR($B$22*0.3048,NA()) | E22: m
A23: Casing shoe TVD | B23: 5573 | C23: ft | D23: =IFERROR($B$23*0.3048,NA()) | E23: m
A24: Open hole diameter | B24: 8.5 | C24: in | D24: =IFERROR($B$24*25.4,NA()) | E24: mm
A25: Last casing ID | B25: 8.681 | C25: in | D25: =IFERROR($B$25*25.4,NA()) | E25: mm
A26: Perforation / reservoir TVD | B26: 5573 | C26: ft | D26: =IFERROR($B$26*0.3048,NA()) | E26: m
A28: Mud & Formation Pressures
A30: Mud & Pressures
A31: Current mud / fluid weight | B31: 12.5 | C31: ppg | D31: =IFERROR($B$31*119.8264,NA()) | E31: kg/m3
A32: Plastic viscosity (PV) | B32: 15 | C32: cP | F32: mPa-s in SI
A33: Yield point (YP) | B33: 12 | F33: lb/100ft2
A34: LOT / FIT equivalent mud weight | B34: 15.2 | C34: ppg | D34: =IFERROR($B$34*119.8264,NA()) | E34: kg/m3
A35: Fracture gradient (at TD/perfs) | B35: 0.79 | C35: psi/ft | D35: =IFERROR($B$35*22.62059,NA()) | E35: kPa/m
A36: Reservoir / formation pressure | B36: 4122 | C36: psi | D36: =IFERROR($B$36*6.894757,NA()) | E36: kPa
A38: Pumps & Kill Parameters
A40: Pumps & Kill
A41: Slow circulating rate pressure (SCR) | B41: 750 | C41: psi | D41: =IFERROR($B$41*6.894757,NA()) | E41: kPa
A42: Pump output | B42: 0.102 | C42: bbl/stk | D42: =IFERROR($B$42*158.9873,NA()) | E42: L/stk
A43: Kill rate | B43: 30 | F43: strokes per minute
A45: Rig & Drill String (for Torque & Drag)
A47: Rig & String
A48: Travelling block + top drive weight | B48: 85 | C48: klbf | D48: =IFERROR($B$48*4.448222,NA()) | E48: kN
A49: Weight on bit (slack-off case) | B49: 15 | C49: klbf | D49: =IFERROR($B$49*4.448222,NA()) | E49: kN
A50: Bit torque | B50: 4000 | C50: ft-lbf | D50: =IFERROR($B$50*1.355818,NA()) | E50: N-m
A51: Tool joint OD | B51: 6.625 | C51: in | D51: =IFERROR($B$51*25.4,NA()) | E51: mm
...

Sheet Tubular Library
A1: Tubular Library - API Catalog
A2: Standard drill pipe, HWDP, collars, casing, tubing and CT dimensions. Feeds the dropdowns and OD/ID auto-fill on the Kill Sheet.
A4: Parameter | B4: Value | C4: Unit | D4: SI Value | E4: SI Unit | F4: Notes / Equation
A6: Catalog
A7: Nominal API dimensions. DP weights are nominal - for string weight use adjusted weight (incl. tool joints, ~7% higher). Pressure ratings are grade-specific: enter them on the Casing & Tubular Design sheet.
A8: Name | B8: OD (in) | C8: ID (in) | D8: Weight (lb/ft) | E8: Capacity (bbl/ft) | F8: Disp. closed (bbl/ft) | G8: Disp. open (bbl/ft) | H8: Wall (in)
A9: DP 3-1/2 13.30# | B9: 3.5 | C9: 2.764 | D9: 13.3 | E9: =$C9^2/1029.4 | F9: =$B9^2/1029.4 | G9: =($B9^2-$C9^2)/1029.4 | H9: =($B9-$C9)/2
A10: DP 4 14.00# | B10: 4 | C10: 3.34 | D10: 14 | E10: =$C10^2/1029.4 | F10: =$B10^2/1029.4 | G10: =($B10^2-$C10^2)/1029.4 | H10: =($B10-$C10)/2
A11: DP 4-1/2 16.60# | B11: 4.5 | C11: 3.826 | D11: 16.6 | E11: =$C11^2/1029.4 | F11: =$B11^2/1029.4 | G11: =($B11^2-$C11^2)/1029.4 | H11: =($B11-$C11)/2
A12: DP 5 19.50# | B12: 5 | C12: 4.276 | D12: 19.5 | E12: =$C12^2/1029.4 | F12: =$B12^2/1029.4 | G12: =($B12^2-$C12^2)/1029.4 | H12: =($B12-$C12)/2
A13: DP 5 25.60# | B13: 5 | C13: 4 | D13: 25.6 | E13: =$C13^2/1029.4 | F13: =$B13^2/1029.4 | G13: =($B13^2-$C13^2)/1029.4 | H13: =($B13-$C13)/2
A14: DP 5-1/2 21.90# | B14: 5.5 | C14: 4.778 | D14: 21.9 | E14: =$C14^2/1029.4 | F14: =$B14^2/1029.4 | G14: =($B14^2-$C14^2)/1029.4 | H14: =($B14-$C14)/2
A15: DP 5-1/2 24.70# | B15: 5.5 | C15: 4.67 | D15: 24.7 | E15: =$C15^2/1029.4 | F15: =$B15^2/1029.4 | G15: =($B15^2-$C15^2)/1029.4 | H15: =($B15-$C15)/2
A16: DP 6-5/8 25.20# | B16: 6.625 | C16: 5.965 | D16: 25.2 | E16: =$C16^2/1029.4 | F16: =$B16^2/1029.4 | G16: =($B16^2-$C16^2)/1029.4 | H16: =($B16-$C16)/2
A17: HWDP 3-1/2 25.3# | B17: 3.5 | C17: 2.063 | D17: 25.3 | E17: =$C17^2/1029.4 | F17: =$B17^2/1029.4 | G17: =($B17^2-$C17^2)/1029.4 | H17: =($B17-$C17)/2
A18: HWDP 4 29.7# | B18: 4 | C18: 2.563 | D18: 29.7 | E18: =$C18^2/1029.4 | F18: =$B18^2/1029.4 | G18: =($B18^2-$C18^2)/1029.4 | H18: =($B18-$C18)/2
A19: HWDP 4-1/2 41.0# | B19: 4.5 | C19: 2.75 | D19: 41 | E19: =$C19^2/1029.4 | F19: =$B19^2/1029.4 | G19: =($B19^2-$C19^2)/1029.4 | H19: =($B19-$C19)/2
A20: HWDP 5 49.3# | B20: 5 | C20: 3 | D20: 49.3 | E20: =$C20^2/1029.4 | F20: =$B20^2/1029.4 | G20: =($B20^2-$C20^2)/1029.4 | H20: =($B20-$C20)/2
... A47: CT 2-3/8 x 0.175w | B47: 2.375 | C47: 2.025 | D47: 4.11 | E47: =$C47^2/1029.4 | F47: =$B47^2/1029.4 | G47: =($B47^2-$C47^2)/1029.4 | H47: =($B47-$C47)/2
A49: Lookup Calculator
A51: Pipe Properties Lookup | F51: Capacity = ID^2/1029.4; Disp closed = OD^2/1029.4; Disp open = (OD^2-ID^2)/1029.4
F52: Type or pick any catalog name (dropdowns available on the Kill Sheet).
A53: Catalog name | B53: DP 5 19.50#
A54: OD | B54: =VLOOKUP($B$53,TL_Table,2,FALSE) | C54: in | D54: =IFERROR($B$54*25.4,NA()) | E54: mm
A55: ID | B55: =VLOOKUP($B$53,TL_Table,3,FALSE) | C55: in | D55: =IFERROR($B$55*25.4,NA()) | E55: mm
A56: Nominal weight | B56: =VLOOKUP($B$53,TL_Table,4,FALSE) | C56: lb/ft | D56: =IFERROR($B$56*1.488164,NA()) | E56: kg/m
A57: Capacity | B57: =$B$55^2/1029.4 | C57: bbl/ft | D57: =IFERROR($B$57*0.5216119,NA()) | E57: m3/m
A58: Displacement (closed end) | B58: =$B$54^2/1029.4 | C58: bbl/ft | D58: =IFERROR($B$58*0.5216119,NA()) | E58: m3/m
A59: Displacement (open end) | B59: =($B$54^2-$B$55^2)/1029.4 | C59: bbl/ft | D59: =IFERROR($B$59*0.5216119,NA()) | E59: m3/m
A60: Hole / casing ID for annulus | B60: 8.681 | C60: in | D60: =IFERROR($B$60*25.4,NA()) | E60: mm
A61: Annular capacity around pipe | B61: =($B$60^2-$B$54^2)/1029.4 | C61: bbl/ft | D61: =IFERROR($B$61*0.5216119,NA()) | E61: m3/m

Sheet Unit Converter
A1: Unit Conversions
A2: Live two-way converters for common oilfield quantities, plus the full factor table
A4: Parameter | B4: Value | C4: Unit | D4: SI Value | E4: SI Unit | F4: Notes / Equation
A6: Live Converters (enter a field-unit value; SI computes)
A8: Field -> SI
F9: Yellow cells are inputs; SI Value column converts live.
A10: Density (ppg) | B10: 12.5 | C10: ppg | D10: =IFERROR($B$10*119.8264,NA()) | E10: kg/m3
A11: Pressure (psi) | B11: 5000 | C11: psi | D11: =IFERROR($B$11*6.894757,NA()) | E11: kPa
A12: Pressure gradient (psi/ft) | B12: 0.65 | C12: psi/ft | D12: =IFERROR($B$12*22.62059,NA()) | E12: kPa/m
A13: Length / depth (ft) | B13: 10000 | C13: ft | D13: =IFERROR($B$13*0.3048,NA()) | E13: m
A14: Diameter (in) | B14: 8.5 | C14: in | D14: =IFERROR($B$14*25.4,NA()) | E14: mm
A15: Volume (bbl) | B15: 500 | C15: bbl | D15: =IFERROR($B$15*0.1589873,NA()) | E15: m3
A16: Volume (small) (gal) | B16: 42 | C16: gal | D16: =IFERROR($B$16*3.785412,NA()) | E16: L
A17: Capacity (bbl/ft) | B17: 0.0459 | C17: bbl/ft | D17: =IFERROR($B$17*0.5216119,NA()) | E17: m3/m
A18: Flow rate (gpm) | B18: 350 | C18: gpm | D18: =IFERROR($B$18*3.785412,NA()) | E18: L/min
A19: Flow rate (bbl/min) | B19: 8.5 | C19: bbl/min | D19: =IFERROR($B$19*0.1589873,NA()) | E19: m3/min
A20: Velocity (ft/min) | B20: 150 | C20: ft/min | D20: =IFERROR($B$20*0.3048,NA()) | E20: m/min
A21: Force (lbf) | B21: 45000 | C21: lbf | D21: =IFERROR($B$21*0.004448222,NA()) | E21: kN
A22: Mass (lbm) | B22: 25000 | C22: lbm | D22: =IFERROR($B$22*0.4535924,NA()) | E22: kg
A23: Weight per length (lb/ft) | B23: 19.5 | C23: lb/ft | D23: =IFERROR($B$23*1.488164,NA()) | E23: kg/m
A24: Power (hp) | B24: 1600 | C24: hp | D24: =IFERROR($B$24*0.7456999,NA()) | E24: kW
A26: Temperature | F26: degC = (degF - 32) / 1.8
A27: Temperature | B27: 250 | F27: degF
A28: Temperature | B28: =($B$27-32)/1.8 | F28: degC
A30: SI -> Field (generic) | F30: Field value = SI value / factor
F31: Enter an SI value and the factor from the table below.
A32: SI value | B32: 1500
A33: Factor (field -> SI) | B33: 6.894757
A34: Field value | B34: =$B$32/$B$33
A36: Conversion Factor Table (multiply field value by factor to get SI)
A38: Field unit | B38: Factor | C38: SI unit
A39: bbl | B39: 0.1589873 | C39: m3
A40: bbl/ft | B40: 0.5216119 | C40: m3/m
A41: bbl/hr | B41: 0.1589873 | C41: m3/hr
A42: bbl/mi | B42: 0.0987974 | C42: m3/km
A43: bbl/min | B43: 0.1589873 | C43: m3/min
A44: bbl/stk | B44: 158.9873 | C44: L/stk
A45: cuft/bbl | B45: 0.1781076 | C45: m3/m3
A46: deg/100ft | B46: 0.984252 | C46: deg/30m
A47: ft | B47: 0.3048 | C47: m
...

Sheet Mud & Hydrostatics
A1: Mud Density & Hydrostatic Pressure
A2: Gradients, hydrostatic pressure, equivalent mud weight, ECD, weight-up and dilution
A4: Parameter | B4: Value | C4: Unit | D4: SI Value | E4: SI Unit | F4: Notes / Equation
A6: Gradients & Hydrostatic Pressure
A8: Pressure Gradient from Mud Weight | F8: Grad [psi/ft] = 0.052 x MW [ppg]
A9: Mud weight (MW) | B9: 12.5 | C9: ppg | D9: =IFERROR($B$9*119.8264,NA()) | E9: kg/m3
A10: Pressure gradient | B10: =0.052*$B$9 | C10: psi/ft | D10: =IFERROR($B$10*22.62059,NA()) | E10: kPa/m
A12: Hydrostatic Pressure | F12: P_hyd [psi] = 0.052 x MW [ppg] x TVD [ft]
F13: Always use true vertical depth, never measured depth.
A14: Mud weight (MW) | B14: 12.5 | C14: ppg | D14: =IFERROR($B$14*119.8264,NA()) | E14: kg/m3
A15: True vertical depth (TVD) | B15: 10000 | C15: ft | D15: =IFERROR($B$15*0.3048,NA()) | E15: m
A16: Hydrostatic pressure (P_hyd) | B16: =0.052*$B$14*$B$15 | C16: psi | D16: =IFERROR($B$16*6.894757,NA()) | E16: kPa
A18: Mud Weight from Pressure Gradient | F18: MW [ppg] = Grad [psi/ft] / 0.052
A19: Pressure gradient | B19: 0.65 | C19: psi/ft | D19: =IFERROR($B$19*22.62059,NA()) | E19: kPa/m
A20: Equivalent mud weight | B20: =$B$19/0.052 | C20: ppg | D20: =IFERROR($B$20*119.8264,NA()) | E20: kg/m3
A22: Equivalent Mud Weight (EMW) at Depth | F22: EMW [ppg] = P [psi] / (0.052 x TVD [ft])
A23: Pressure at depth (P) | B23: 6500 | C23: psi | D23: =IFERROR($B$23*6.894757,NA()) | E23: kPa
A24: True vertical depth (TVD) | B24: 10000 | C24: ft | D24: =IFERROR($B$24*0.3048,NA()) | E24: m
A25: Equivalent mud weight (EMW) | B25: =$B$23/(0.052*$B$24) | C25: ppg | D25: =IFERROR($B$25*119.8264,NA()) | E25: kg/m3
A27: Hydrostatic Pressure of a Column of Multiple Fluids | F27: P_hyd = 0.052 x [ MW1 x L1_tvd + MW2 x L2_tvd ]
F28: Extend by summing 0.052 x MW x TVD-length for each fluid in the column.
A29: Fluid 1 density | B29: 8.6 | C29: ppg | D29: =IFERROR($B$29*119.8264,NA()) | E29: kg/m3
A30: Fluid 1 vertical length | B30: 4000 | C30: ft | D30: =IFERROR($B$30*0.3048,NA()) | E30: m
A31: Fluid 2 density | B31: 12.5 | C31: ppg | D31: =IFERROR($B$31*119.8264,NA()) | E31: kg/m3
A32: Fluid 2 vertical length | B32: 6000 | C32: ft | D32: =IFERROR($B$32*0.3048,NA()) | E32: m
A33: Total hydrostatic pressure | B33: =0.052*($B$29*$B$30+$B$31*$B$32) | C33: psi | D33: =IFERROR($B$33*6.894757,NA()) | E33: kPa
A35: Density Conversions
A37: Specific Gravity <-> Mud Weight | F37: MW [ppg] = SG x 8.345; SG = MW / 8.345
A38: Specific gravity (SG) | B38: 1.2
A39: Mud weight | B39: =$B$38*8.345 | C39: ppg | D39: =IFERROR($B$39*119.8264,NA()) | E39: kg/m3
A40: Mud weight (MW) | B40: 12.5 | C40: ppg | D40: =IFERROR($B$40*119.8264,NA()) | E40: kg/m3
A41: Specific gravity | B41: =$B$40/8.345
A43: Mud Weight <-> lb/ft3 | F43: MW [lb/ft3] = MW [ppg] x 7.48
A44: Mud weight | B44: 12.5 | C44: ppg | D44: =IFERROR($B$44*119.8264,NA()) | E44: kg/m3
A45: Density | B45: =$B$44*7.48 | C45: lb/ft3 | D45: =IFERROR($B$45*16.01846,NA()) | E45: kg/m3
A47: ECD & Annular Friction
A49: Equivalent Circulating Density (ECD) | F49: ECD [ppg] = MW + APL / (0.052 x TVD)
F50: APL = annular pressure loss while circulating.
A51: Mud weight (MW) | B51: 12.5 | C51: ppg | D51: =IFERROR($B$51*119.8264,NA()) | E51: kg/m3
A52: Annular pressure loss (APL) | B52: 200 | C52: psi | D52: =IFERROR($B$52*6.894757,NA()) | E52: kPa
...

Sheet Capacities & Displacement
A1: Capacities, Displacement & Pump Output
A2: Pipe and annular capacities, hole volume, pump output, circulation strokes, tripping and slug
A4: Parameter | B4: Value | C4: Unit | D4: SI Value | E4: SI Unit | F4: Notes / Equation
A6: Pipe, Annulus & Hole Capacities
A8: Pipe (Internal) Capacity | F8: C_pipe [bbl/ft] = ID^2 / 1029.4
A9: Pipe inside diameter (ID) | B9: 4.276 | C9: in | D9: =IFERROR($B$9*25.4,NA()) | E9: mm
A10: Pipe capacity | B10: =$B$9^2/1029.4 | C10: bbl/ft | D10: =IFERROR($B$10*0.5216119,NA()) | E10: m3/m | F10: 5 in 19.5 lb/ft drill pipe shown.
A12: Annular Capacity | F12: C_ann [bbl/ft] = (Dh^2 - Dp^2) / 1029.4
A13: Hole (or casing ID) diameter (Dh) | B13: 8.5 | C13: in | D13: =IFERROR($B$13*25.4,NA()) | E13: mm
A14: Pipe outside diameter (Dp) | B14: 5 | C14: in | D14: =IFERROR($B$14*25.4,NA()) | E14: mm
A15: Annular capacity | B15: =($B$13^2-$B$14^2)/1029.4 | C15: bbl/ft | D15: =IFERROR($B$15*0.5216119,NA()) | E15: m3/m
A17: Pipe Displacement | F17: Closed-end [bbl/ft] = OD^2 / 1029.4; Open-end (steel) [bbl/ft] = (OD^2 - ID^2) / 1029.4
F18: Open-end = steel displacement (tripping with open pipe). Closed-end = capacity + steel (plugged bit / float).
A19: Pipe outside diameter (OD) | B19: 5 | C19: in | D19: =IFERROR($B$19*25.4,NA()) | E19: mm
A20: Pipe inside diameter (ID) | B20: 4.276 | C20: in | D20: =IFERROR($B$20*25.4,NA()) | E20: mm
A21: Closed-end displacement | B21: =$B$19^2/1029.4 | C21: bbl/ft | D21: =IFERROR($B$21*0.5216119,NA()) | E21: m3/m
A22: Open-end (steel) displacement | B22: =($B$19^2-$B$20^2)/1029.4 | C22: bbl/ft | D22: =IFERROR($B$22*0.5216119,NA()) | E22: m3/m
A24: Hole Volume | F24: V [bbl] = Dh^2 / 1029.4 x L x (1 + washout)
F25: Washout entered as a fraction (0.10 = 10% over-gauge).
A26: Hole diameter (Dh) | B26: 8.5 | C26: in | D26: =IFERROR($B$26*25.4,NA()) | E26: mm
A27: Hole length | B27: 10000 | C27: ft | D27: =IFERROR($B$27*0.3048,NA()) | E27: m
A28: Washout factor | B28: 0.1 | F28: Fraction of excess over gauge hole.
A29: Hole volume | B29: =$B$26^2/1029.4*$B$27*(1+$B$28) | C29: bbl | D29: =IFERROR($B$29*0.1589873,NA()) | E29: m3
A31: Pump Output & Flow Rate
A33: Triplex Pump Output | F33: Q [bbl/stk] = 0.000243 x D_liner^2 x L_stroke x eff
F34: Single-acting, three cylinders. D and stroke in inches; eff as a fraction (0.95-0.98 typical).
A35: Liner diameter (D) | B35: 6 | C35: in | D35: =IFERROR($B$35*25.4,NA()) | E35: mm
A36: Stroke length (L) | B36: 12 | C36: in | D36: =IFERROR($B$36*25.4,NA()) | E36: mm
A37: Volumetric efficiency | B37: 0.95
A38: Pump output | B38: =0.000243*$B$35^2*$B$36*$B$37 | C38: bbl/stk | D38: =IFERROR($B$38*158.9873,NA()) | E38: L/stk
A40: Duplex Pump Output | F40: Q [bbl/stk] = 0.000162 x L_stroke x (2 x D_liner^2 - d_rod^2) x eff
F41: Double-acting, two cylinders; d = piston rod diameter. Eff 0.85-0.90 typical.
A42: Liner diameter (D) | B42: 6.5 | C42: in | D42: =IFERROR($B$42*25.4,NA()) | E42: mm
A43: Rod diameter (d) | B43: 2.5 | C43: in | D43: =IFERROR($B$43*25.4,NA()) | E43: mm
A44: Stroke length (L) | B44: 14 | C44: in | D44: =IFERROR($B$44*25.4,NA()) | E44: mm
A45: Volumetric efficiency | B45: 0.9
A46: Pump output | B46: =0.000162*$B$44*(2*$B$42^2-$B$43^2)*$B$45 | C46: bbl/stk | D46: =IFERROR($B$46*158.9873,NA()) | E46: L/stk
A48: Pump Flow Rate from Stroke Rate | F48: Q [bbl/min] = output [bbl/stk] x SPM; Q [gpm] = bbl/min x 42
A49: Pump output | B49: 0.0997 | C49: bbl/stk | D49: =IFERROR($B$49*158.9873,NA()) | E49: L/stk
A50: Pump speed | B50: 60 | C50: spm | F50: Strokes per minute.
...

Sheet Kill Sheet
A1: Well Control Kill Sheet - Surface BOP (Vertical / Deviated / Horizontal)
A2: Component-level volumes, kill mud weight, ICP/FCP, survey-driven pressure schedule and auto-generated kill plot
A4: Parameter | B4: Value | C4: Unit | D4: SI Value | E4: SI Unit | F4: Notes / Equation
A6: 1. Pre-Recorded Data (light blue = linked to Well Data sheet)
A8: Well & Pump Data
F9: Linked to the Well Data sheet - update there, or overwrite locally. The schedule below also reads the Directional Survey sheet directly.
A10: Current mud weight (OMW) | B10: =WD_OMW | C10: ppg | D10: =IFERROR($B$10*119.8264,NA()) | E10: kg/m3 | F10: Linked to Well Data sheet - overwrite locally if this well differs.
A11: Bit / hole measured depth (MD) | B11: =WD_MD | C11: ft | D11: =IFERROR($B$11*0.3048,NA()) | E11: m | F11: Linked to Well Data sheet - overwrite locally if this well differs.
A12: Bit / hole true vertical depth (TVD) | B12: =WD_TVD | C12: ft | D12: =IFERROR($B$12*0.3048,NA()) | E12: m | F12: Linked to Well Data sheet - overwrite locally if this well differs.
A13: Casing shoe MD | B13: =WD_ShoeMD | C13: ft | D13: =IFERROR($B$13*0.3048,NA()) | E13: m | F13: Linked to Well Data sheet - overwrite locally if this well differs.
A14: Casing shoe TVD | B14: =WD_ShoeTVD | C14: ft | D14: =IFERROR($B$14*0.3048,NA()) | E14: m | F14: Linked to Well Data sheet - overwrite locally if this well differs.
A15: LOT / FIT equivalent mud weight | B15: =WD_LOT | C15: ppg | D15: =IFERROR($B$15*119.8264,NA()) | E15: kg/m3 | F15: Linked to Well Data sheet - overwrite locally if this well differs.
A16: Slow circulating rate pressure (SCR) | B16: =WD_SCR | C16: psi | D16: =IFERROR($B$16*6.894757,NA()) | E16: kPa | F16: Linked to Well Data sheet - overwrite locally if this well differs.
A17: Pump output | B17: =WD_SPR | C17: bbl/stk | D17: =IFERROR($B$17*158.9873,NA()) | E17: L/stk | F17: Linked to Well Data sheet - overwrite locally if this well differs.
A18: Kill rate | B18: =WD_KillRate | F18: strokes per minute (spm); linked to Well Data.
A20: Maximum Allowable Annular Surface Pressure (MAASP) | F20: MAASP = (LOT_EMW - MW) x 0.052 x Shoe TVD
F21: Valid only while the annulus above the shoe contains mud of density MW. Rounding rule: maximized values round UP to whole psi (1000.1 -> 1001).
A22: MAASP (initial, with current mud) | B22: =ROUNDUP(ROUND(($B$15-$B$10)*0.052*$B$14,6),0) | C22: psi | D22: =IFERROR($B$22*6.894757,NA()) | E22: kPa
A24: 2. Drill String Volume (component by component, top down)
A25: Pick components from the dropdown (Tubular Library) - OD/ID auto-fill. For non-catalog pipe, type any name and overwrite OD/ID. Unused rows stay blank.
A26: Component | B26: OD (in) | C26: ID (in) | D26: Length (ft) | E26: Capacity (bbl/ft) | F26: Volume (bbl) | G26: Top MD (ft) | H26: Cum vol at top (bbl)
A27: DP 5 19.50# | B27: =IF($A27="","",IFERROR(VLOOKUP($A27,TL_Table,2,FALSE),"")) | C27: =IF($A27="","",IFERROR(VLOOKUP($A27,TL_Table,3,FALSE),"")) | D27: 9700 | E27: =IF($C27="",0,$C27^2/1029.4) | F27: =$E27*IF($D27="",0,$D27) | G27: =0 | H27: =0
A28: HWDP 5 49.3# | B28: =IF($A28="","",IFERROR(VLOOKUP($A28,TL_Table,2,FALSE),"")) | C28: =IF($A28="","",IFERROR(VLOOKUP($A28,TL_Table,3,FALSE),"")) | D28: 500 | E28: =IF($C28="",0,$C28^2/1029.4) | F28: =$E28*IF($D28="",0,$D28) | G28: =$G27+IF($D27="",0,$D27) | H28: =$H27+$F27
A29: DC 6-1/2 92# | B29: =IF($A29="","",IFERROR(VLOOKUP($A29,TL_Table,2,FALSE),"")) | C29: =IF($A29="","",IFERROR(VLOOKUP($A29,TL_Table,3,FALSE),"")) | D29: 300 | E29: =IF($C29="",0,$C29^2/1029.4) | F29: =$E29*IF($D29="",0,$D29) | G29: =$G28+IF($D28="",0,$D28) | H29: =$H28+$F28
B30: =IF($A30="","",IFERROR(VLOOKUP($A30,TL_Table,2,FALSE),"")) | C30: =IF($A30="","",IFERROR(VLOOKUP($A30,TL_Table,3,FALSE),"")) | E30: =IF($C30="",0,$C30^2/1029.4) | F30: =$E30*IF($D30="",0,$D30) | G30: =$G29+IF($D29="",0,$D29) | H30: =$H29+$F29
B31: =IF($A31="","",IFERROR(VLOOKUP($A31,TL_Table,2,FALSE),"")) | C31: =IF($A31="","",IFERROR(VLOOKUP($A31,TL_Table,3,FALSE),"")) | E31: =IF($C31="",0,$C31^2/1029.4) | F31: =$E31*IF($D31="",0,$D31) | G31: =$G30+IF($D30="",0,$D30) | H31: =$H30+$F30
B32: =IF($A32="","",IFERROR(VLOOKUP($A32,TL_Table,2,FALSE),"")) | C32: =IF($A32="","",IFERROR(VLOOKUP($A32,TL_Table,3,FALSE),"")) | E32: =IF($C32="",0,$C32^2/1029.4) | F32: =$E32*IF($D32="",0,$D32) | G32: =$G31+IF($D31="",0,$D31) | H32: =$H31+$F31
B33: =IF($A33="","",IFERROR(VLOOKUP($A33,TL_Table,2,FALSE),"")) | C33: =IF($A33="","",IFERROR(VLOOKUP($A33,TL_Table,3,FALSE),"")) | E33: =IF($C33="",0,$C33^2/1029.4) | F33: =$E33*IF($D33="",0,$D33) | G33: =$G32+IF($D32="",0,$D32) | H33: =$H32+$F32
B34: =IF($A34="","",IFERROR(VLOOKUP($A34,TL_Table,2,FALSE),"")) | C34: =IF($A34="","",IFERROR(VLOOKUP($A34,TL_Table,3,FALSE),"")) | E34: =IF($C34="",0,$C34^2/1029.4) | F34: =$E34*IF($D34="",0,$D34) | G34: =$G33+IF($D33="",0,$D33) | H34: =$H33+$F33
A36: Drill String Totals | F36: Capacity = ID^2/1029.4 [bbl/ft]; Strokes = Volume / Pump output
A37: Total string length | B37: =SUM($D$27:$D$34) | C37: ft | D37: =IFERROR($B$37*0.3048,NA()) | E37: m
A38: Length check vs bit MD | B38: =IF($B$37=$B$11,"OK - matches bit MD","CHECK: components <> bit MD")
A39: Drill string volume | B39: =SUM($F$27:$F$34) | C39: bbl | D39: =IFERROR($B$39*0.1589873,NA()) | E39: m3
A40: Strokes surface to bit | B40: =ROUNDUP(ROUND($B$39/$B$17,6),0)
A41: Time surface to bit | B41: =$B$40/$B$18 | F41: minutes at kill rate
A43: 3. Annulus Volume (bottom up)
A44: Section | B44: Hole/Csg ID (in) | C44: Pipe OD (in) | D44: Length (ft) | E44: Capacity (bbl/ft) | F44: Volume (bbl)
A45: DC x open hole | B45: 8.5 | C45: 6.5 | D45: 300 | E45: =IF(OR($B45="",$C45=""),0,($B45^2-$C45^2)/1029.4) | F45: =$E45*IF($D45="",0,$D45)
A46: DP x open hole | B46: 8.5 | C46: 5 | D46: 4300 | E46: =IF(OR($B46="",$C46=""),0,($B46^2-$C46^2)/1029.4) | F46: =$E46*IF($D46="",0,$D46)
A47: DP x casing | B47: 8.681 | C47: 5 | D47: 5900 | E47: =IF(OR($B47="",$C47=""),0,($B47^2-$C47^2)/1029.4) | F47: =$E47*IF($D47="",0,$D47)
...

Sheet Kill Form
A1: WELL KILL SHEET - SURFACE BOP
A3: Well | B3: =WD_Well | D3: Date | E3: =WD_Date
A4: Rig | B4: =WD_Rig | D4: Engineer | E4: =WD_Engineer
A6: PRE-RECORDED DATA
A7: Current mud weight | B7: ='Kill Sheet'!$B$10 | C7: ppg
A8: MD / TVD at bit | B8: ='Kill Sheet'!$B$11 | C8: ft | E8: STROKES | F8: DP PSI
A9: Shoe MD / TVD | B9: ='Kill Sheet'!$B$13 | C9: ft | E9: ='Kill Sheet'!$B95 | F9: ='Kill Sheet'!$E95
A10: LOT EMW | B10: ='Kill Sheet'!$B$15 | C10: ppg | E10: ='Kill Sheet'!$B96 | F10: ='Kill Sheet'!$E96
A11: SCR pressure | B11: ='Kill Sheet'!$B$16 | C11: psi | E11: ='Kill Sheet'!$B97 | F11: ='Kill Sheet'!$E97
A12: Pump output | B12: ='Kill Sheet'!$B$17 | C12: bbl/stk | E12: ='Kill Sheet'!$B98 | F12: ='Kill Sheet'!$E98
A13: Kill rate | B13: ='Kill Sheet'!$B$18 | C13: spm | E13: ='Kill Sheet'!$B99 | F13: ='Kill Sheet'!$E99
A14: MAASP (initial) | B14: ='Kill Sheet'!$B$22 | C14: psi | E14: ='Kill Sheet'!$B100 | F14: ='Kill Sheet'!$E100
E15: ='Kill Sheet'!$B101 | F15: ='Kill Sheet'!$E101
A16: VOLUMES & STROKES | E16: ='Kill Sheet'!$B102 | F16: ='Kill Sheet'!$E102
A17: Drill string volume | B17: ='Kill Sheet'!$B$39 | C17: bbl | E17: ='Kill Sheet'!$B103 | F17: ='Kill Sheet'!$E103
A18: Strokes surface to bit | B18: ='Kill Sheet'!$B$40 | C18: stk | E18: ='Kill Sheet'!$B104 | F18: ='Kill Sheet'!$E104
A19: Annulus volume | B19: ='Kill Sheet'!$B$53 | C19: bbl | E19: ='Kill Sheet'!$B105 | F19: ='Kill Sheet'!$E105
A20: Strokes bit to surface | B20: ='Kill Sheet'!$B$54 | C20: stk | E20: ='Kill Sheet'!$B106 | F20: ='Kill Sheet'!$E106
A21: Total circulation | B21: ='Kill Sheet'!$B$55 | C21: stk | E21: ='Kill Sheet'!$B107 | F21: ='Kill Sheet'!$E107
E22: ='Kill Sheet'!$B108 | F22: ='Kill Sheet'!$E108
A23: KICK DATA | E23: ='Kill Sheet'!$B109 | F23: ='Kill Sheet'!$E109
A24: SIDPP | B24: ='Kill Sheet'!$B$62 | C24: psi | E24: ='Kill Sheet'!$B110 | F24: ='Kill Sheet'!$E110
A25: SICP | B25: ='Kill Sheet'!$B$63 | C25: psi | E25: ='Kill Sheet'!$B111 | F25: ='Kill Sheet'!$E111
A26: Pit gain | B26: ='Kill Sheet'!$B$64 | C26: bbl | E26: ='Kill Sheet'!$B112 | F26: ='Kill Sheet'!$E112
E27: ='Kill Sheet'!$B113 | F27: ='Kill Sheet'!$E113
A28: KILL DATA | E28: ='Kill Sheet'!$B114 | F28: ='Kill Sheet'!$E114
A29: Kill mud weight (rounded up) | B29: ='Kill Sheet'!$B$71 | C29: ppg | E29: ='Kill Sheet'!$B115 | F29: ='Kill Sheet'!$E115
A30: ICP | B30: ='Kill Sheet'!$B$74 | C30: psi | E30: Survey-driven schedule
A31: FCP | B31: ='Kill Sheet'!$B$75 | C31: psi
A32: psi per 100 strokes (rounded down) | B32: ='Kill Sheet'!$B$76 | C32: psi
A33: Formation pressure | B33: ='Kill Sheet'!$B$79 | C33: psi
A34: MAASP after kill | B34: ='Kill Sheet'!$B$90 | C34: psi
A37: Driller: ____________ | C37: Toolpusher: ____________ | E37: Company rep: ____________
A39: Generated from the live Kill Sheet - values update automatically. Verify against stabilised shut-in pressures before pumping.

Sheet Kill Sheet - Subsea
A1: Well Control Kill Sheet - Subsea BOP Supplement
A2: Choke line friction corrections, choke line displacement, riser margin and riser-disconnect hydrostatics (use with the main Kill Sheet)
A4: Parameter | B4: Value | C4: Unit | D4: SI Value | E4: SI Unit | F4: Notes / Equation
A6: Subsea Well Data
A8: Rig, Water Depth & Choke Line
F9: Yellow inputs are subsea-specific for THIS calc (the Well Data master defaults to a land / surface-BOP well). CLF should be MEASURED, not calculated, where possible - record it during slow-rate circulation up the choke line.
A10: Water depth | B10: 1500 | C10: ft | D10: =IFERROR($B$10*0.3048,NA()) | E10: m
A11: Air gap (RKB to sea level) | B11: 75 | C11: ft | D11: =IFERROR($B$11*0.3048,NA()) | E11: m
A12: Choke line length | B12: 1650 | C12: ft | D12: =IFERROR($B$12*0.3048,NA()) | E12: m | F12: Approx. water depth + air gap + stack height.
A13: Choke line ID | B13: 3 | C13: in | D13: =IFERROR($B$13*25.4,NA()) | E13: mm
A14: Choke line friction (CLF) at kill rate | B14: 250 | C14: psi | D14: =IFERROR($B$14*6.894757,NA()) | E14: kPa | F14: Measured at the kill rate circulating up the choke line.
A16: Linked Well Data
F17: Light blue = linked to the Well Data sheet; overwrite locally if this well differs.
A18: Current mud weight (OMW) | B18: =WD_OMW | C18: ppg | D18: =IFERROR($B$18*119.8264,NA()) | E18: kg/m3 | F18: Linked to Well Data sheet - overwrite locally if this well differs.
A19: Bit / TD true vertical depth (TVD) | B19: =WD_TVD | C19: ft | D19: =IFERROR($B$19*0.3048,NA()) | E19: m | F19: Linked to Well Data sheet - overwrite locally if this well differs.
A20: Casing shoe TVD | B20: =WD_ShoeTVD | C20: ft | D20: =IFERROR($B$20*0.3048,NA()) | E20: m | F20: Linked to Well Data sheet - overwrite locally if this well differs.
A21: LOT / FIT equivalent mud weight | B21: =WD_LOT | C21: ppg | D21: =IFERROR($B$21*119.8264,NA()) | E21: kg/m3 | F21: Linked to Well Data sheet - overwrite locally if this well differs.
A22: Slow circulating rate pressure (SCR) | B22: =WD_SCR | C22: psi | D22: =IFERROR($B$22*6.894757,NA()) | E22: kPa | F22: Linked to Well Data sheet - overwrite locally if this well differs.
A23: Pump output | B23: =WD_SPR | C23: bbl/stk | D23: =IFERROR($B$23*158.9873,NA()) | E23: L/stk | F23: Linked to Well Data sheet - overwrite locally if this well differs.
A25: Choke Line
A27: Choke Line Volume & Displacement | F27: Capacity = ID^2 / 1029.4 [bbl/ft]; Strokes = Volume / Pump output
F28: Small ID over a long length: the choke line holds only a few barrels but adds significant friction at kill rate.
A29: Choke line capacity | B29: =$B$13^2/1029.4 | C29: bbl/ft | D29: =IFERROR($B$29*0.5216119,NA()) | E29: m3/m
A30: Choke line volume | B30: =$B$29*$B$12 | C30: bbl | D30: =IFERROR($B$30*0.1589873,NA()) | E30: m3
A31: Strokes to displace choke line | B31: =ROUNDUP(ROUND($B$30/$B$23,6),0)
A33: CLF-Corrected Pressures
A35: Shut-In Pressures
F36: Allow pressures to stabilise; watch for gas migration on SIDPP.
A37: Shut-in drill pipe pressure (SIDPP) | B37: 500 | C37: psi | D37: =IFERROR($B$37*6.894757,NA()) | E37: kPa
A38: Shut-in casing pressure (SICP) | B38: 700 | C38: psi | D38: =IFERROR($B$38*6.894757,NA()) | E38: kPa
A40: MAASP - Static & Dynamic | F40: MAASP_static = (LOT_EMW - MW) x 0.052 x Shoe TVD; MAASP_dynamic = MAASP_static - CLF
F41: With a subsea stack the choke line friction acts on the ANNULUS side: while circulating up the choke line the shoe feels surface choke pressure + CLF, so the allowable surface reading drops by CLF. Rounding rule: maximized values round UP to whole psi.
A42: Static MAASP (well shut in) | B42: =ROUNDUP(ROUND(($B$21-$B$18)*0.052*$B$20,6),0) | C42: psi | D42: =IFERROR($B$42*6.894757,NA()) | E42: kPa
A43: Dynamic MAASP (circulating up choke line) | B43: =ROUNDUP(ROUND($B$42-$B$14,6),0) | C43: psi | D43: =IFERROR($B$43*6.894757,NA()) | E43: kPa
A45: Bringing the Pump to Kill Speed | F45: ICP = SCR + SIDPP (DP side unchanged); Choke pressure to hold = SICP - CLF
F46: The DP-side target (ICP) is unchanged by the subsea stack. But as the pump is brought up, CLF develops in the choke line on the annulus side and adds to bottomhole pressure. To keep BHP constant, open the choke so the surface CASING gauge falls to SICP - CLF while bringing the pump to kill speed (rather than holding SICP as on a surface stack).
A47: Initial circulating pressure (ICP) | B47: =$B$22+$B$37 | C47: psi | D47: =IFERROR($B$47*6.894757,NA()) | E47: kPa | F47: SCR should itself be measured circulating up the choke line.
A48: Choke pressure while bringing pump up | B48: =MAX(0,$B$38-$B$14) | C48: psi | D48: =IFERROR($B$48*6.894757,NA()) | E48: kPa
A50: Kill Mud & Gas at Surface
A52: Kill Mud Weight (KMW) | F52: KMW = OMW + SIDPP / (0.052 x TVD)
...

Sheet Well Control
A1: Well Control
A2: Kick tolerance, MAASP, trip/swab/riser margins, gas behavior, kill weight and volumetric method
A4: Parameter | B4: Value | C4: Unit | D4: SI Value | E4: SI Unit | F4: Notes / Equation
A6: Kick Tolerance & MAASP
A8: MAASP (Maximum Allowable Annular Surface Pressure) | F8: MAASP [psi] = 0.052 x (FG - MW) x TVD_shoe
F9: FG = fracture gradient at shoe from leak-off test, expressed as EMW. Recalculate whenever mud weight changes.
A10: Fracture gradient at shoe (FG) | B10: 14.5 | C10: ppg | D10: =IFERROR($B$10*119.8264,NA()) | E10: kg/m3 | F10: From LOT/FIT, as equivalent mud weight.
A11: Current mud weight (MW) | B11: 12.5 | C11: ppg | D11: =IFERROR($B$11*119.8264,NA()) | E11: kg/m3
A12: Shoe TVD | B12: 5000 | C12: ft | D12: =IFERROR($B$12*0.3048,NA()) | E12: m
A13: MAASP | B13: =ROUNDUP(ROUND(0.052*($B$10-$B$11)*$B$12,6),0) | C13: psi | D13: =IFERROR($B$13*6.894757,NA()) | E13: kPa | F13: Rounding rule: maximized values round UP to whole psi (1000.1 -> 1001).
A15: Kick Tolerance (Volume Basis, Gas at Shoe) | F15: H_max = [P_frac - P_form + 0.052 x MW x (TVD - TVD_shoe)] / (0.052 x MW - G_gas); V_shoe = H_max x C_ann; KT [bbl] = V_shoe x P_frac / P_form
F16: Single gas bubble, no gas cut above it, Boyle expansion from bottom to shoe (isothermal, Z ignored). KT is the largest influx at bottomhole conditions that can be circulated out without breaking down the shoe.
A17: Fracture gradient at shoe (FG) | B17: 14.5 | C17: ppg | D17: =IFERROR($B$17*119.8264,NA()) | E17: kg/m3
A18: Mud weight (MW) | B18: 12.5 | C18: ppg | D18: =IFERROR($B$18*119.8264,NA()) | E18: kg/m3
A19: Shoe TVD | B19: 5000 | C19: ft | D19: =IFERROR($B$19*0.3048,NA()) | E19: m
A20: Well TVD | B20: 10000 | C20: ft | D20: =IFERROR($B$20*0.3048,NA()) | E20: m
A21: Design SIDPP (kick overpressure) | B21: 350 | C21: psi | D21: =IFERROR($B$21*6.894757,NA()) | E21: kPa | F21: Anticipated shut-in drill pipe pressure for the design kick.
A22: Gas gradient | B22: 0.1 | C22: psi/ft | D22: =IFERROR($B$22*22.62059,NA()) | E22: kPa/m | F22: 0.10-0.15 psi/ft typical for gas.
A23: Annular capacity at shoe/BHA | B23: 0.0459 | C23: bbl/ft | D23: =IFERROR($B$23*0.5216119,NA()) | E23: m3/m
A24: Fracture pressure at shoe | B24: =0.052*$B$17*$B$19 | C24: psi | D24: =IFERROR($B$24*6.894757,NA()) | E24: kPa
A25: Formation (kick) pressure | B25: =0.052*$B$18*$B$20+$B$21 | C25: psi | D25: =IFERROR($B$25*6.894757,NA()) | E25: kPa
A26: Max influx height at shoe | B26: =MAX(0,($B$24-$B$25+0.052*$B$18*($B$20-$B$19))/(0.052*$B$18-$B$22)) | C26: ft | D26: =IFERROR($B$26*0.3048,NA()) | E26: m
A27: Max influx volume at shoe | B27: =$B$26*$B$23 | C27: bbl | D27: =IFERROR($B$27*0.1589873,NA()) | E27: m3
A28: Kick tolerance (at bottomhole) | B28: =$B$27*$B$24/$B$25 | C28: bbl | D28: =IFERROR($B$28*0.1589873,NA()) | E28: m3 | F28: Compare with realistic kick detection volume; if smaller, set casing or raise MW policy.
A30: Margins
A32: Trip Margin / Swab Margin | F32: TM [ppg] = YP / (11.7 x (Dh - Dp))
F33: Overbalance added to cover swab pressures when pulling out (trip margin) or, equally, the swab reduction expected running in. Field approximation from yield point.
A34: Mud yield point (YP) | B34: 12 | F34: lb/100 ft2 from viscometer.
A35: Hole diameter (Dh) | B35: 8.5 | C35: in | D35: =IFERROR($B$35*25.4,NA()) | E35: mm
A36: Pipe outside diameter (Dp) | B36: 5 | C36: in | D36: =IFERROR($B$36*25.4,NA()) | E36: mm
A37: Well TVD | B37: 10000 | C37: ft | D37: =IFERROR($B$37*0.3048,NA()) | E37: m
A38: Trip / swab margin | B38: =$B$34/(11.7*($B$35-$B$36)) | C38: ppg | D38: =IFERROR($B$38*119.8264,NA()) | E38: kg/m3
A39: Equivalent overbalance | B39: =0.052*$B$38*$B$37 | C39: psi | D39: =IFERROR($B$39*6.894757,NA()) | E39: kPa
A41: Riser Margin (Floating Rigs) | F41: MW_req = (MW x TVD - MW_sw x WD) / (TVD - WD - AG); RM = MW_req - MW
F42: Mud weight increment so that, after riser disconnect, seawater above the mudline still balances bottomhole pressure. AG = air gap (RKB to sea level). Often impractical in deep water.
A43: Current mud weight (MW) | B43: 12.5 | C43: ppg | D43: =IFERROR($B$43*119.8264,NA()) | E43: kg/m3
A44: Well TVD (from RKB) | B44: 10000 | C44: ft | D44: =IFERROR($B$44*0.3048,NA()) | E44: m
A45: Water depth (WD) | B45: 3000 | C45: ft | D45: =IFERROR($B$45*0.3048,NA()) | E45: m
A46: Air gap (AG) | B46: 75 | C46: ft | D46: =IFERROR($B$46*0.3048,NA()) | E46: m
A47: Seawater density | B47: 8.55 | C47: ppg | D47: =IFERROR($B$47*119.8264,NA()) | E47: kg/m3
...

Sheet Hydraulics
A1: Drilling Hydraulics
A2: Annular velocity, cuttings transport, Bingham and power-law rheology, annular losses, ECD, surge and swab
A4: Parameter | B4: Value | C4: Unit | D4: SI Value | E4: SI Unit | F4: Notes / Equation
A6: Velocities & Cuttings Transport
A8: Annular Velocity | F8: AV [ft/min] = 24.5 x Q / (Dh^2 - Dp^2)
F9: Q in gpm, diameters in inches. Rule of thumb: keep AV above ~100-120 ft/min in vertical wells.
A10: Flow rate (Q) | B10: 600 | C10: gpm | D10: =IFERROR($B$10*3.785412,NA()) | E10: L/min
A11: Hole diameter (Dh) | B11: 8.5 | C11: in | D11: =IFERROR($B$11*25.4,NA()) | E11: mm
A12: Pipe outside diameter (Dp) | B12: 5 | C12: in | D12: =IFERROR($B$12*25.4,NA()) | E12: mm
A13: Annular velocity | B13: =24.5*$B$10/($B$11^2-$B$12^2) | C13: ft/min | D13: =IFERROR($B$13*0.3048,NA()) | E13: m/min
A15: Pipe (Internal) Velocity | F15: V_pipe [ft/min] = 24.5 x Q / ID^2
A16: Flow rate (Q) | B16: 600 | C16: gpm | D16: =IFERROR($B$16*3.785412,NA()) | E16: L/min
A17: Pipe inside diameter (ID) | B17: 4.276 | C17: in | D17: =IFERROR($B$17*25.4,NA()) | E17: mm
A18: Pipe velocity | B18: =24.5*$B$16/$B$17^2 | C18: ft/min | D18: =IFERROR($B$18*0.3048,NA()) | E18: m/min
A20: Cuttings Slip Velocity & Transport Ratio | F20: V_slip [ft/min] = 92.6 x SQRT( Dc x (MW_c - MW) / MW ); TR = (AV - V_slip) / AV x 100
F21: Turbulent (Newtonian) slip form, drag coefficient ~1.5; cuttings SG 2.6 = 21.7 ppg. Ignores mud rheology support, so it is conservative in viscous muds. TR > 50% is generally adequate hole cleaning in near-vertical hole.
A22: Cutting diameter (Dc) | B22: 0.25 | C22: in | D22: =IFERROR($B$22*25.4,NA()) | E22: mm
A23: Cuttings density | B23: 21.7 | C23: ppg | D23: =IFERROR($B$23*119.8264,NA()) | E23: kg/m3 | F23: SG 2.6 shale/sand.
A24: Mud weight (MW) | B24: 12.5 | C24: ppg | D24: =IFERROR($B$24*119.8264,NA()) | E24: kg/m3
A25: Flow rate (Q) | B25: 600 | C25: gpm | D25: =IFERROR($B$25*3.785412,NA()) | E25: L/min
A26: Hole diameter (Dh) | B26: 8.5 | C26: in | D26: =IFERROR($B$26*25.4,NA()) | E26: mm
A27: Pipe outside diameter (Dp) | B27: 5 | C27: in | D27: =IFERROR($B$27*25.4,NA()) | E27: mm
A28: Annular velocity | B28: =24.5*$B$25/($B$26^2-$B$27^2) | C28: ft/min | D28: =IFERROR($B$28*0.3048,NA()) | E28: m/min
A29: Cuttings slip velocity | B29: =92.6*SQRT($B$22*($B$23-$B$24)/$B$24) | C29: ft/min | D29: =IFERROR($B$29*0.3048,NA()) | E29: m/min
A30: Net cuttings rise velocity | B30: =$B$28-$B$29 | C30: ft/min | D30: =IFERROR($B$30*0.3048,NA()) | E30: m/min
A31: Transport ratio | B31: =($B$28-$B$29)/$B$28*100 | C31: %
A33: Rheology from Viscometer Readings
A35: Bingham Plastic: PV & YP | F35: PV [cP] = theta600 - theta300; YP [lb/100ft2] = theta300 - PV
F36: Standard 600/300 rpm Fann dial readings.
A37: Dial reading at 600 rpm (theta600) | B37: 65 | F37: Fann dial degrees.
A38: Dial reading at 300 rpm (theta300) | B38: 40 | F38: Fann dial degrees.
A39: Plastic viscosity (PV) | B39: =$B$37-$B$38 | F39: cP.
A40: Yield point (YP) | B40: =$B$38-$B$39 | F40: lb/100 ft2.
A42: Power Law: n & K | F42: n = 3.32 x LOG(theta600 / theta300); K = 510 x theta300 / 511^n
F43: K in eq. centipoise (dyne-s^n/100 cm2). LOG is base 10.
A44: Dial reading at 600 rpm (theta600) | B44: 65
A45: Dial reading at 300 rpm (theta300) | B45: 40
A46: Flow behavior index (n) | B46: =3.32*LOG($B$44/$B$45)
A47: Consistency index (K) | B47: =510*$B$45/511^$B$46 | F47: eq. cP.
A49: Annular Pressure Loss & ECD
...

Sheet Bit Hydraulics
A1: Bit Hydraulics
A2: Total flow area, nozzle velocity, bit pressure drop, hydraulic horsepower, HSI and jet impact force
A4: Parameter | B4: Value | C4: Unit | D4: SI Value | E4: SI Unit | F4: Notes / Equation
A6: Nozzles & Flow Area
A8: Total Flow Area (TFA) | F8: TFA [in2] = PI()/4 x sum( (d/32)^2 ) for each nozzle, d in 1/32 in
F9: Three-nozzle bit shown; enter 0 for blanked nozzles and extend the sum for more nozzles.
A10: Nozzle 1 size | B10: 13 | F10: 1/32 in.
A11: Nozzle 2 size | B11: 13 | F11: 1/32 in.
A12: Nozzle 3 size | B12: 14 | F12: 1/32 in.
A13: Total flow area (TFA) | B13: =PI()/4*(($B$10/32)^2+($B$11/32)^2+($B$12/32)^2) | C13: in2 | D13: =IFERROR($B$13*6.4516,NA()) | E13: cm2
A15: Nozzle (Jet) Velocity | F15: Vn [ft/s] = 0.32086 x Q / TFA
F16: Uses TFA computed above. Typical target 350-450 ft/s for adequate bottomhole cleaning.
A17: Flow rate (Q) | B17: 450 | C17: gpm | D17: =IFERROR($B$17*3.785412,NA()) | E17: L/min
A18: Nozzle velocity (Vn) | B18: =0.32086*$B$17/$B$13 | C18: ft/s | D18: =IFERROR($B$18*0.3048,NA()) | E18: m/s
A20: Bit Pressure Drop & Horsepower
A22: Pressure Drop Across Bit | F22: dPb [psi] = Q^2 x MW / (12042 x TFA^2)
F23: Nozzle discharge coefficient 0.95 built into the constant. Uses Q and TFA from above.
A24: Mud weight (MW) | B24: 12.5 | C24: ppg | D24: =IFERROR($B$24*119.8264,NA()) | E24: kg/m3
A25: Surface (standpipe) pressure | B25: 3200 | C25: psi | D25: =IFERROR($B$25*6.894757,NA()) | E25: kPa
A26: Bit pressure drop (dPb) | B26: =$B$17^2*$B$24/(12042*$B$13^2) | C26: psi | D26: =IFERROR($B$26*6.894757,NA()) | E26: kPa
A27: Percent of surface pressure at bit | B27: =$B$26/$B$25*100 | C27: %
A29: Hydraulic Horsepower & HSI | F29: HHP = P x Q / 1714; HSI = HHP_bit / (PI()/4 x D_bit^2)
F30: HSI 2.5-5+ hp/in2 is a common target for effective PDC/roller-cone cleaning.
A31: Bit diameter | B31: 8.5 | C31: in | D31: =IFERROR($B$31*25.4,NA()) | E31: mm
A32: System hydraulic horsepower | B32: =$B$25*$B$17/1714 | C32: hp | D32: =IFERROR($B$32*0.7456999,NA()) | E32: kW
A33: Bit hydraulic horsepower | B33: =$B$26*$B$17/1714 | C33: hp | D33: =IFERROR($B$33*0.7456999,NA()) | E33: kW
A34: Hydraulic horsepower per in2 (HSI) | B34: =$B$33/(PI()/4*$B$31^2) | C34: hp/in2 | D34: =IFERROR($B$34*0.1155886,NA()) | E34: kW/cm2
A36: Jet Impact Force
A38: Hydraulic Impact Force | F38: IF [lbf] = 0.01823 x Cd x Q x SQRT( MW x dPb )
F39: Uses Q, MW and dPb from above. Impact per unit bit area is a useful comparison between bit runs.
A40: Nozzle discharge coefficient (Cd) | B40: 0.95
A41: Jet impact force (IF) | B41: =0.01823*$B$40*$B$17*SQRT($B$24*$B$26) | C41: lbf | D41: =IFERROR($B$41*0.004448222,NA()) | E41: kN
A42: Impact force per in2 of bit area | B42: =$B$41/(PI()/4*$B$31^2) | F42: lbf/in2 of bit face.
A44: Optimization Guidance
A46: Rules of Thumb for Bit Hydraulics Optimization
F47: Compare the 'percent of surface pressure at bit' output above against these targets.
A48: Maximum bit hydraulic horsepower: | F48: achieved when dPb is about 65% of surface pressure (friction exponent u ~ 1.86).
A49: Maximum jet impact force: | F49: achieved when dPb is about 48% of surface pressure.
A50: Practical window: | F50: most operators size nozzles for 50-65% of surface pressure at the bit, subject to minimum annular velocity for hole cleaning and maximum pump pressure/liner rating.
A51: Nozzle selection: | F51: adjust nozzle sizes (TFA) rather than flow rate first; flow rate is usually set by hole cleaning and motor/MWD requirements.

Sheet Drill String & Tension
A1: Drill String Weight, Tension & Vibration
A2: Buoyancy, hook load, margin of overpull, collar length for WOB, stretch, slip crush, critical RPM, ton-miles
A4: Parameter | B4: Value | C4: Unit | D4: SI Value | E4: SI Unit | F4: Notes / Equation
A6: Buoyancy & String Weight
A8: Buoyancy Factor | F8: BF = (65.5 - MW) / 65.5
F9: 65.5 ppg = density of steel. Multiply air weights by BF to get buoyed weight in mud.
A10: Mud weight (MW) | B10: 12.5 | C10: ppg | D10: =IFERROR($B$10*119.8264,NA()) | E10: kg/m3
A11: Buoyancy factor (BF) | B11: =(65.5-$B$10)/65.5
A13: Buoyed String Weight (Hook Load) | F13: W_buoyed = (L_dp x W_dp + L_dc x W_dc) x BF
F14: Air weights per foot include tool joints (use 'approximate weight' from pipe tables). Add HWDP as a third term if run.
A15: Drill pipe length | B15: 9400 | C15: ft | D15: =IFERROR($B$15*0.3048,NA()) | E15: m
A16: Drill pipe weight (incl. tool joints) | B16: 20.89 | C16: lb/ft | D16: =IFERROR($B$16*1.488164,NA()) | E16: kg/m
A17: Drill collar length | B17: 600 | C17: ft | D17: =IFERROR($B$17*0.3048,NA()) | E17: m
A18: Drill collar weight | B18: 92 | C18: lb/ft | D18: =IFERROR($B$18*1.488164,NA()) | E18: kg/m | F18: 6-1/2 in x 2-13/16 in collars.
A19: Mud weight (MW) | B19: 12.5 | C19: ppg | D19: =IFERROR($B$19*119.8264,NA()) | E19: kg/m3
A20: Buoyancy factor (BF) | B20: =(65.5-$B$19)/65.5
A21: Buoyed string weight | B21: =($B$15*$B$16+$B$17*$B$18)*$B$20 | C21: lbf | D21: =IFERROR($B$21*0.004448222,NA()) | E21: kN
A23: Tension, Overpull & Slips
A25: Maximum Allowable Pull & Margin of Overpull | F25: Max pull = T_yield x DF; MOP = Max pull - buoyed hook load; SF = T_yield / hook load
F26: T_yield = pipe body tensile yield for the weakest (usually top) joint and wear class. DF of 0.90 on new pipe is common; use premium-class ratings for worn pipe. Hook load defaults to the buoyed string weight computed above.
A27: Pipe body tensile yield | B27: 553830 | C27: lbf | D27: =IFERROR($B$27*0.004448222,NA()) | E27: kN | F27: 5 in 19.5 lb/ft G-105, new.
A28: Tension design factor (DF) | B28: 0.9
A29: Hook load (buoyed) | B29: 203400 | C29: lbf | D29: =IFERROR($B$29*0.004448222,NA()) | E29: kN
A30: Maximum allowable pull | B30: =$B$27*$B$28 | C30: lbf | D30: =IFERROR($B$30*0.004448222,NA()) | E30: kN
A31: Margin of overpull (MOP) | B31: =$B$30-$B$29 | C31: lbf | D31: =IFERROR($B$31*0.004448222,NA()) | E31: kN | F31: Keep at least 50,000-100,000 lbf for stuck-pipe contingency.
A32: Safety factor in tension | B32: =$B$27/$B$29
A34: Drill Collar Length for Desired WOB | F34: L_dc [ft] = WOB x SF / (W_dc x BF x COS(angle))
F35: Keeps the neutral point inside the collars (drill pipe never in compression). SF 1.10-1.20 places the neutral point 10-20% below the top of the collars.
A36: Desired weight on bit (WOB) | B36: 45000 | C36: lbf | D36: =IFERROR($B$36*0.004448222,NA()) | E36: kN
A37: Safety factor (SF) | B37: 1.15
A38: Drill collar weight | B38: 92 | C38: lb/ft | D38: =IFERROR($B$38*1.488164,NA()) | E38: kg/m
A39: Mud weight (MW) | B39: 12.5 | C39: ppg | D39: =IFERROR($B$39*119.8264,NA()) | E39: kg/m3
A40: Hole inclination | B40: 10 | C40: deg
A41: Drill collar length required | B41: =$B$36*$B$37/($B$38*(65.5-$B$39)/65.5*COS(RADIANS($B$40))) | C41: ft | D41: =IFERROR($B$41*0.3048,NA()) | E41: m
A43: Slip Crush Ratio | F43: SH/SA = SQRT( 1 + D x K/(2 x Ls) + (D x K/(2 x Ls))^2 ); Max static load = T_yield / (SH/SA)
F44: Reinhold-Spiri (API RP 7G) hoop-to-axial stress ratio. K = lateral load factor (~4.0 for 9 deg 27.5 min taper, friction 0.08); Ls = slip contact length. Hook loads above the max static load risk crushing the pipe in the slips.
A45: Pipe outside diameter (D) | B45: 5 | C45: in | D45: =IFERROR($B$45*25.4,NA()) | E45: mm
A46: Lateral load factor (K) | B46: 4
A47: Slip contact length (Ls) | B47: 16 | C47: in | D47: =IFERROR($B$47*25.4,NA()) | E47: mm
A48: Pipe body tensile yield | B48: 553830 | C48: lbf | D48: =IFERROR($B$48*0.004448222,NA()) | E48: kN
...

Sheet Directional Drilling
A1: Directional Drilling
A2: Dogleg severity, minimum curvature surveys, closure, radius of curvature, build geometry, slide vs rotate
A4: Parameter | B4: Value | C4: Unit | D4: SI Value | E4: SI Unit | F4: Notes / Equation
A6: Surveys & Dogleg
A8: Dogleg Severity Between Two Surveys | F8: DL [deg] = ACOS( COS(I1) x COS(I2) + SIN(I1) x SIN(I2) x COS(A2 - A1) ); DLS = DL x 100 / CL
F9: I = inclination, A = azimuth, CL = course length (MD between surveys). Typical limits: 3-5 deg/100 ft for drill pipe fatigue, less for casing running.
A10: Inclination at survey 1 (I1) | B10: 20 | C10: deg
A11: Azimuth at survey 1 (A1) | B11: 45 | C11: deg
A12: Inclination at survey 2 (I2) | B12: 22 | C12: deg
A13: Azimuth at survey 2 (A2) | B13: 48 | C13: deg
A14: Course length (CL) | B14: 100 | C14: ft | D14: =IFERROR($B$14*0.3048,NA()) | E14: m
A15: Dogleg angle (DL) | B15: =DEGREES(ACOS(COS(RADIANS($B$10))*COS(RADIANS($B$12))+SIN(RADIANS($B$10))*SIN(RADIANS($B$12))*COS(RADIANS($B$13-$B$11)))) | C15: deg
A16: Dogleg severity (DLS) | B16: =$B$15*100/$B$14 | C16: deg/100ft | D16: =IFERROR($B$16*0.984252,NA()) | E16: deg/30m
A18: Minimum Curvature Between Two Surveys | F18: RF = 2/DL x TAN(DL/2) (DL in radians); dTVD = CL/2 x (COS I1 + COS I2) x RF; dN = CL/2 x (SIN I1 x COS A1 + SIN I2 x COS A2) x RF; dE = CL/2 x (SIN I1 x SIN A1 + SIN I2 x SIN A2) x RF
F19: Industry-standard survey calculation. RF = 1 when the dogleg is zero (straight course).
A20: Inclination at survey 1 (I1) | B20: 20 | C20: deg
A21: Azimuth at survey 1 (A1) | B21: 45 | C21: deg
A22: Inclination at survey 2 (I2) | B22: 22 | C22: deg
A23: Azimuth at survey 2 (A2) | B23: 48 | C23: deg
A24: Course length (CL) | B24: 100 | C24: ft | D24: =IFERROR($B$24*0.3048,NA()) | E24: m
A25: Dogleg angle (DL) | B25: =DEGREES(ACOS(COS(RADIANS($B$20))*COS(RADIANS($B$22))+SIN(RADIANS($B$20))*SIN(RADIANS($B$22))*COS(RADIANS($B$23-$B$21)))) | C25: deg
A26: Ratio factor (RF) | B26: =IF($B$25=0,1,2/RADIANS($B$25)*TAN(RADIANS($B$25)/2))
A27: Delta TVD | B27: =$B$24/2*(COS(RADIANS($B$20))+COS(RADIANS($B$22)))*$B$26 | C27: ft | D27: =IFERROR($B$27*0.3048,NA()) | E27: m
A28: Delta North | B28: =$B$24/2*(SIN(RADIANS($B$20))*COS(RADIANS($B$21))+SIN(RADIANS($B$22))*COS(RADIANS($B$23)))*$B$26 | C28: ft | D28: =IFERROR($B$28*0.3048,NA()) | E28: m
A29: Delta East | B29: =$B$24/2*(SIN(RADIANS($B$20))*SIN(RADIANS($B$21))+SIN(RADIANS($B$22))*SIN(RADIANS($B$23)))*$B$26 | C29: ft | D29: =IFERROR($B$29*0.3048,NA()) | E29: m
A31: Closure & Vertical Section | F31: Closure = SQRT(N^2 + E^2); Closure azimuth = ATAN2(N, E); VS = closure x COS(VS azimuth - closure azimuth)
F32: N and E are cumulative coordinates from the wellhead. Vertical section is the closure projected onto the plan (target) direction.
A33: Cumulative North (+N/-S) | B33: 1450 | C33: ft | D33: =IFERROR($B$33*0.3048,NA()) | E33: m
A34: Cumulative East (+E/-W) | B34: 1620 | C34: ft | D34: =IFERROR($B$34*0.3048,NA()) | E34: m
A35: Vertical section plane azimuth | B35: 45 | C35: deg
A36: Closure distance | B36: =SQRT($B$33^2+$B$34^2) | C36: ft | D36: =IFERROR($B$36*0.3048,NA()) | E36: m
A37: Closure azimuth | B37: =MOD(DEGREES(ATAN2($B$33,$B$34)),360) | C37: deg
A38: Vertical section (VS) | B38: =$B$36*COS(RADIANS($B$35-$B$37)) | C38: ft | D38: =IFERROR($B$38*0.3048,NA()) | E38: m
A40: Build Planning
A42: Radius of Curvature & Build Section Length | F42: R [ft] = 18000 / (PI() x BUR); MD_build = (I_end - I_start) x 100 / BUR
F43: BUR in deg/100 ft. R is the radius of the build arc in the vertical plane.
A44: Build-up rate (BUR) | B44: 3 | C44: deg/100ft | D44: =IFERROR($B$44*0.984252,NA()) | E44: deg/30m
A45: Starting inclination | B45: 0 | C45: deg
A46: Ending inclination | B46: 35 | C46: deg
A47: Radius of curvature (R) | B47: =18000/(PI()*$B$44) | C47: ft | D47: =IFERROR($B$47*0.3048,NA()) | E47: m
...

Sheet Directional Survey
A1: Directional Survey - Minimum Curvature
A2: Paste MD / Inc / Azi stations; TVD, N/E, VS and DLS compute per row. Charts and the Kill Sheet schedule update automatically.
A3: Vertical section direction | B3: 90 | C3: deg | D3: TVD at TD | E3: =LOOKUP(9.99E+307,D7:D106) | F3: ft | G3: Max DLS | H3: =MAX(H8:H106) | I3: deg/100ft
A4: Parameter | B4: Value | C4: Unit | D4: SI Value | E4: SI Unit | F4: Notes / Equation
A5: Survey Stations - enter MD / Inc / Azi (yellow). Row 1 is the tie-in (TVD/NS/EW also inputs there). MD must strictly increase; no blank rows between stations; last station must reach bit/TD measured depth.
A6: MD (ft) | B6: Inc (deg) | C6: Azi (deg) | D6: TVD (ft) | E6: VS (ft) | F6: N/S (ft) | G6: E/W (ft) | H6: DLS (deg/100ft) | I6: MDh* | J6: TVDh* | K6: DL* | L6: RF* | M6: VS_c* | N6: TVD_c* | O6: EW_c* | P6: NS_c*
A7: 0 | B7: 0 | C7: 0 | D7: 0 | E7: =F7*COS(RADIANS($B$3))+G7*SIN(RADIANS($B$3)) | F7: 0 | G7: 0 | I7: =IF(A7="",9.9E+99,A7) | J7: =IF(D7="",0,D7) | M7: =IF($A7="",NA(),E7) | N7: =IF($A7="",NA(),D7) | O7: =IF($A7="",NA(),G7) | P7: =IF($A7="",NA(),F7)
A8: 1000 | B8: 0 | C8: 0 | D8: =IF(K8="","",D7+(A8-A7)/2*(COS(RADIANS(B7))+COS(RADIANS(B8)))*L8) | E8: =IF(D8="","",F8*COS(RADIANS($B$3))+G8*SIN(RADIANS($B$3))) | F8: =IF(K8="","",ROUND(F7+(A8-A7)/2*(SIN(RADIANS(B7))*COS(RADIANS(C7))+SIN(RADIANS(B8))*COS(RADIANS(C8)))*L8,4)) | G8: =IF(K8="","",ROUND(G7+(A8-A7)/2*(SIN(RADIANS(B7))*SIN(RADIANS(C7))+SIN(RADIANS(B8))*SIN(RADIANS(C8)))*L8,4)) | H8: =IF(K8="","",IF(A8=A7,0,K8*100/(A8-A7))) | I8: =IF(A8="",9.9E+99,A8) | J8: =IF(D8="",0,D8) | K8: =IF(OR(A8="",A7=""),"",DEGREES(ACOS(MIN(1,MAX(-1,COS(RADIANS(B7))*COS(RADIANS(B8))+SIN(RADIANS(B7))*SIN(RADIANS(B8))*COS(RADIANS(C8-C7))))))) | L8: =IF(K8="","",IF(K8=0,1,2/RADIANS(K8)*TAN(RADIANS(K8)/2))) | M8: =IF($A8="",NA(),E8) | N8: =IF($A8="",NA(),D8) | O8: =IF($A8="",NA(),G8) | P8: =IF($A8="",NA(),F8)
A9: 2000 | B9: 0 | C9: 0 | D9: =IF(K9="","",D8+(A9-A8)/2*(COS(RADIANS(B8))+COS(RADIANS(B9)))*L9) | E9: =IF(D9="","",F9*COS(RADIANS($B$3))+G9*SIN(RADIANS($B$3))) | F9: =IF(K9="","",ROUND(F8+(A9-A8)/2*(SIN(RADIANS(B8))*COS(RADIANS(C8))+SIN(RADIANS(B9))*COS(RADIANS(C9)))*L9,4)) | G9: =IF(K9="","",ROUND(G8+(A9-A8)/2*(SIN(RADIANS(B8))*SIN(RADIANS(C8))+SIN(RADIANS(B9))*SIN(RADIANS(C9)))*L9,4)) | H9: =IF(K9="","",IF(A9=A8,0,K9*100/(A9-A8))) | I9: =IF(A9="",9.9E+99,A9) | J9: =IF(D9="",0,D9) | K9: =IF(OR(A9="",A8=""),"",DEGREES(ACOS(MIN(1,MAX(-1,COS(RADIANS(B8))*COS(RADIANS(B9))+SIN(RADIANS(B8))*SIN(RADIANS(B9))*COS(RADIANS(C9-C8))))))) | L9: =IF(K9="","",IF(K9=0,1,2/RADIANS(K9)*TAN(RADIANS(K9)/2))) | M9: =IF($A9="",NA(),E9) | N9: =IF($A9="",NA(),D9) | O9: =IF($A9="",NA(),G9) | P9: =IF($A9="",NA(),F9)
A10: 3000 | B10: 0 | C10: 0 | D10: =IF(K10="","",D9+(A10-A9)/2*(COS(RADIANS(B9))+COS(RADIANS(B10)))*L10) | E10: =IF(D10="","",F10*COS(RADIANS($B$3))+G10*SIN(RADIANS($B$3))) | F10: =IF(K10="","",ROUND(F9+(A10-A9)/2*(SIN(RADIANS(B9))*COS(RADIANS(C9))+SIN(RADIANS(B10))*COS(RADIANS(C10)))*L10,4)) | G10: =IF(K10="","",ROUND(G9+(A10-A9)/2*(SIN(RADIANS(B9))*SIN(RADIANS(C9))+SIN(RADIANS(B10))*SIN(RADIANS(C10)))*L10,4)) | H10: =IF(K10="","",IF(A10=A9,0,K10*100/(A10-A9))) | I10: =IF(A10="",9.9E+99,A10) | J10: =IF(D10="",0,D10) | K10: =IF(OR(A10="",A9=""),"",DEGREES(ACOS(MIN(1,MAX(-1,COS(RADIANS(B9))*COS(RADIANS(B10))+SIN(RADIANS(B9))*SIN(RADIANS(B10))*COS(RADIANS(C10-C9))))))) | L10: =IF(K10="","",IF(K10=0,1,2/RADIANS(K10)*TAN(RADIANS(K10)/2))) | M10: =IF($A10="",NA(),E10) | N10: =IF($A10="",NA(),D10) | O10: =IF($A10="",NA(),G10) | P10: =IF($A10="",NA(),F10)
A11: 4000 | B11: 0 | C11: 0 | D11: =IF(K11="","",D10+(A11-A10)/2*(COS(RADIANS(B10))+COS(RADIANS(B11)))*L11) | E11: =IF(D11="","",F11*COS(RADIANS($B$3))+G11*SIN(RADIANS($B$3))) | F11: =IF(K11="","",ROUND(F10+(A11-A10)/2*(SIN(RADIANS(B10))*COS(RADIANS(C10))+SIN(RADIANS(B11))*COS(RADIANS(C11)))*L11,4)) | G11: =IF(K11="","",ROUND(G10+(A11-A10)/2*(SIN(RADIANS(B10))*SIN(RADIANS(C10))+SIN(RADIANS(B11))*SIN(RADIANS(C11)))*L11,4)) | H11: =IF(K11="","",IF(A11=A10,0,K11*100/(A11-A10))) | I11: =IF(A11="",9.9E+99,A11) | J11: =IF(D11="",0,D11) | K11: =IF(OR(A11="",A10=""),"",DEGREES(ACOS(MIN(1,MAX(-1,COS(RADIANS(B10))*COS(RADIANS(B11))+SIN(RADIANS(B10))*SIN(RADIANS(B11))*COS(RADIANS(C11-C10))))))) | L11: =IF(K11="","",IF(K11=0,1,2/RADIANS(K11)*TAN(RADIANS(K11)/2))) | M11: =IF($A11="",NA(),E11) | N11: =IF($A11="",NA(),D11) | O11: =IF($A11="",NA(),G11) | P11: =IF($A11="",NA(),F11)
